Workbook

Sheet Market_Summary
A1: PlanPulse market summary, week of 2026-10-26 (simulated data)
A3: Market | B3: SKUs | C3: Forecast WAPE | D3: Forecast bias | E3: Avg days of cover | F3: High stockout risk SKUs | G3: Below safety stock SKUs | H3: Excess value | I3: OTIF | J3: Open actions | K3: Overdue actions
A4: APAC | B4: =COUNTIFS(SKU_KPIs!$A:$A,$A4) | C4: =SUMIFS(Accuracy_SKU!$E:$E,Accuracy_SKU!$A:$A,$A4)/SUMIFS(Accuracy_SKU!$C:$C,Accuracy_SKU!$A:$A,$A4) | D4: =(SUMIFS(Accuracy_SKU!$D:$D,Accuracy_SKU!$A:$A,$A4)-SUMIFS(Accuracy_SKU!$C:$C,Accuracy_SKU!$A:$A,$A4))/SUMIFS(Accuracy_SKU!$C:$C,Accuracy_SKU!$A:$A,$A4) | E4: =AVERAGEIFS(SKU_KPIs!$I:$I,SKU_KPIs!$A:$A,$A4) | F4: =COUNTIFS(SKU_KPIs!$A:$A,$A4,SKU_KPIs!$Q:$Q,"HIGH") | G4: =SUMIFS(SKU_KPIs!$J:$J,SKU_KPIs!$A:$A,$A4) | H4: =SUMIFS(SKU_KPIs!$R:$R,SKU_KPIs!$A:$A,$A4) | I4: =SUMIFS(OTIF_Supplier!$F:$F,OTIF_Supplier!$A:$A,$A4)/SUMIFS(OTIF_Supplier!$C:$C,OTIF_Supplier!$A:$A,$A4) | J4: =COUNTIFS(Actions!$B:$B,$A4,Actions!$I:$I,"Open")+COUNTIFS(Actions!$B:$B,$A4,Actions!$I:$I,"In Progress") | K4: =COUNTIFS(Actions!$B:$B,$A4,Actions!$J:$J,">0")
A5: India | B5: =COUNTIFS(SKU_KPIs!$A:$A,$A5) | C5: =SUMIFS(Accuracy_SKU!$E:$E,Accuracy_SKU!$A:$A,$A5)/SUMIFS(Accuracy_SKU!$C:$C,Accuracy_SKU!$A:$A,$A5) | D5: =(SUMIFS(Accuracy_SKU!$D:$D,Accuracy_SKU!$A:$A,$A5)-SUMIFS(Accuracy_SKU!$C:$C,Accuracy_SKU!$A:$A,$A5))/SUMIFS(Accuracy_SKU!$C:$C,Accuracy_SKU!$A:$A,$A5) | E5: =AVERAGEIFS(SKU_KPIs!$I:$I,SKU_KPIs!$A:$A,$A5) | F5: =COUNTIFS(SKU_KPIs!$A:$A,$A5,SKU_KPIs!$Q:$Q,"HIGH") | G5: =SUMIFS(SKU_KPIs!$J:$J,SKU_KPIs!$A:$A,$A5) | H5: =SUMIFS(SKU_KPIs!$R:$R,SKU_KPIs!$A:$A,$A5) | I5: =SUMIFS(OTIF_Supplier!$F:$F,OTIF_Supplier!$A:$A,$A5)/SUMIFS(OTIF_Supplier!$C:$C,OTIF_Supplier!$A:$A,$A5) | J5: =COUNTIFS(Actions!$B:$B,$A5,Actions!$I:$I,"Open")+COUNTIFS(Actions!$B:$B,$A5,Actions!$I:$I,"In Progress") | K5: =COUNTIFS(Actions!$B:$B,$A5,Actions!$J:$J,">0")
A6: MENA-PAK | B6: =COUNTIFS(SKU_KPIs!$A:$A,$A6) | C6: =SUMIFS(Accuracy_SKU!$E:$E,Accuracy_SKU!$A:$A,$A6)/SUMIFS(Accuracy_SKU!$C:$C,Accuracy_SKU!$A:$A,$A6) | D6: =(SUMIFS(Accuracy_SKU!$D:$D,Accuracy_SKU!$A:$A,$A6)-SUMIFS(Accuracy_SKU!$C:$C,Accuracy_SKU!$A:$A,$A6))/SUMIFS(Accuracy_SKU!$C:$C,Accuracy_SKU!$A:$A,$A6) | E6: =AVERAGEIFS(SKU_KPIs!$I:$I,SKU_KPIs!$A:$A,$A6) | F6: =COUNTIFS(SKU_KPIs!$A:$A,$A6,SKU_KPIs!$Q:$Q,"HIGH") | G6: =SUMIFS(SKU_KPIs!$J:$J,SKU_KPIs!$A:$A,$A6) | H6: =SUMIFS(SKU_KPIs!$R:$R,SKU_KPIs!$A:$A,$A6) | I6: =SUMIFS(OTIF_Supplier!$F:$F,OTIF_Supplier!$A:$A,$A6)/SUMIFS(OTIF_Supplier!$C:$C,OTIF_Supplier!$A:$A,$A6) | J6: =COUNTIFS(Actions!$B:$B,$A6,Actions!$I:$I,"Open")+COUNTIFS(Actions!$B:$B,$A6,Actions!$I:$I,"In Progress") | K6: =COUNTIFS(Actions!$B:$B,$A6,Actions!$J:$J,">0")
A7: South Africa | B7: =COUNTIFS(SKU_KPIs!$A:$A,$A7) | C7: =SUMIFS(Accuracy_SKU!$E:$E,Accuracy_SKU!$A:$A,$A7)/SUMIFS(Accuracy_SKU!$C:$C,Accuracy_SKU!$A:$A,$A7) | D7: =(SUMIFS(Accuracy_SKU!$D:$D,Accuracy_SKU!$A:$A,$A7)-SUMIFS(Accuracy_SKU!$C:$C,Accuracy_SKU!$A:$A,$A7))/SUMIFS(Accuracy_SKU!$C:$C,Accuracy_SKU!$A:$A,$A7) | E7: =AVERAGEIFS(SKU_KPIs!$I:$I,SKU_KPIs!$A:$A,$A7) | F7: =COUNTIFS(SKU_KPIs!$A:$A,$A7,SKU_KPIs!$Q:$Q,"HIGH") | G7: =SUMIFS(SKU_KPIs!$J:$J,SKU_KPIs!$A:$A,$A7) | H7: =SUMIFS(SKU_KPIs!$R:$R,SKU_KPIs!$A:$A,$A7) | I7: =SUMIFS(OTIF_Supplier!$F:$F,OTIF_Supplier!$A:$A,$A7)/SUMIFS(OTIF_Supplier!$C:$C,OTIF_Supplier!$A:$A,$A7) | J7: =COUNTIFS(Actions!$B:$B,$A7,Actions!$I:$I,"Open")+COUNTIFS(Actions!$B:$B,$A7,Actions!$I:$I,"In Progress") | K7: =COUNTIFS(Actions!$B:$B,$A7,Actions!$J:$J,">0")
A8: All markets | B8: =SUM(B4:B7) | C8: =SUM(Accuracy_SKU!$E:$E)/SUM(Accuracy_SKU!$C:$C) | D8: =(SUM(Accuracy_SKU!$D:$D)-SUM(Accuracy_SKU!$C:$C))/SUM(Accuracy_SKU!$C:$C) | E8: =AVERAGE(SKU_KPIs!$I:$I) | F8: =SUM(F4:F7) | G8: =SUM(G4:G7) | H8: =SUM(H4:H7) | I8: =SUM(OTIF_Supplier!$F:$F)/SUM(OTIF_Supplier!$C:$C) | J8: =SUM(J4:J7) | K8: =SUM(K4:K7)
A10: Excess value is in simulated currency units. Cover uses the next 4 weeks of system forecast.

Sheet Legend
A1: PlanPulse KPI workbook | B1: Week of 2026-10-26. SIMULATED DATA, not real ISCP or company data.
A2: EXCESS_DAYS | B2: 120
A3: Meaning | B3: Cover above this many days counts as excess (SKU_KPIs column R)
A5: Sheet | B5: What it holds
A6: Market_Summary | B6: Per-market KPIs. Every number is a formula over the other sheets.
A7: SKU_KPIs | B7: One row per SKU with clean stock data. Columns I, J, N, O, R are formulas; the rest are values from the DuckDB KPI layer.
A8: Accuracy_SKU | B8: Forecast accuracy for every SKU with sales and forecast, including SKUs held out of SKU_KPIs for stock data problems. Market WAPE and bias read from here.
A9: OTIF_Supplier | B9: Closed POs in the trailing window. Percent columns are formulas.
A10: Actions / Exceptions / DQ_Results | B10: Values exported from the tracker, exception list and data-quality checks.
A12: Definitions | B12: Days of cover = on hand / (average weekly forecast, next 4 weeks / 7). WAPE = sum |forecast - actual| / sum actual. Bias = (sum forecast - sum actual) / sum actual. OTIF = POs on time AND in full / POs received.
A13: Stockout risk | B13: HIGH = projected stockout earlier than the lead time (a new order cannot land in time). MEDIUM = stockout within 8 weeks but after lead time. Value from SQL, not a formula.

Sheet SKU_KPIs
A1: market | B1: sku | C1: category | D1: on_hand | E1: safety_stock | F1: lead_time_days | G1: avg_weekly_fcst_4w | H1: unit_cost | I1: days_of_cover | J1: below_safety | K1: actual_units_8w | L1: forecast_units_8w | M1: abs_err_8w | N1: wape | O1: bias | P1: stockout_week | Q1: stockout_risk | R1: excess_value
A2: APAC | B2: AP-ACC-002 | C2: Accessories | D2: 118 | E2: 27 | F2: 25 | G2: 61.5 | H2: 859.96 | I2: =IF(AND(ISNUMBER(G2),G2>0),D2/(G2/7),"") | J2: =IF(AND(ISNUMBER(E2),D2<E2),1,0) | K2: 547 | L2: 472 | M2: 79 | N2: =IF(AND(ISNUMBER(K2),K2>0),M2/K2,"") | O2: =IF(AND(ISNUMBER(K2),K2>0),(L2-K2)/K2,"") | Q2: LOW | R2: =IF(ISNUMBER(G2),MAX(0,D2-Legend!$B$2*G2/7)*H2,0)
A3: APAC | B3: AP-ACC-006 | C3: Accessories | D3: 145 | E3: 22 | F3: 25 | G3: 51 | H3: 333.54 | I3: =IF(AND(ISNUMBER(G3),G3>0),D3/(G3/7),"") | J3: =IF(AND(ISNUMBER(E3),D3<E3),1,0) | K3: 316 | L3: 327 | M3: 65 | N3: =IF(AND(ISNUMBER(K3),K3>0),M3/K3,"") | O3: =IF(AND(ISNUMBER(K3),K3>0),(L3-K3)/K3,"") | Q3: LOW | R3: =IF(ISNUMBER(G3),MAX(0,D3-Legend!$B$2*G3/7)*H3,0)
A4: APAC | B4: AP-ACC-010 | C4: Accessories | D4: 1035 | E4: 35 | F4: 33 | G4: 44 | H4: 461.95 | I4: =IF(AND(ISNUMBER(G4),G4>0),D4/(G4/7),"") | J4: =IF(AND(ISNUMBER(E4),D4<E4),1,0) | K4: 365 | L4: 373 | M4: 58 | N4: =IF(AND(ISNUMBER(K4),K4>0),M4/K4,"") | O4: =IF(AND(ISNUMBER(K4),K4>0),(L4-K4)/K4,"") | Q4: LOW | R4: =IF(ISNUMBER(G4),MAX(0,D4-Legend!$B$2*G4/7)*H4,0)
A5: APAC | B5: AP-ACC-018 | C5: Accessories | D5: 220 | E5: 34 | F5: 35 | G5: 49 | H5: 736.57 | I5: =IF(AND(ISNUMBER(G5),G5>0),D5/(G5/7),"") | J5: =IF(AND(ISNUMBER(E5),D5<E5),1,0) | K5: 411 | L5: 403 | M5: 60 | N5: =IF(AND(ISNUMBER(K5),K5>0),M5/K5,"") | O5: =IF(AND(ISNUMBER(K5),K5>0),(L5-K5)/K5,"") | Q5: LOW | R5: =IF(ISNUMBER(G5),MAX(0,D5-Legend!$B$2*G5/7)*H5,0)
A6: APAC | B6: AP-ACC-022 | C6: Accessories | D6: 86 | E6: 29 | F6: 17 | G6: 68 | H6: 316.64 | I6: =IF(AND(ISNUMBER(G6),G6>0),D6/(G6/7),"") | J6: =IF(AND(ISNUMBER(E6),D6<E6),1,0) | K6: 440 | L6: 612 | M6: 172 | N6: =IF(AND(ISNUMBER(K6),K6>0),M6/K6,"") | O6: =IF(AND(ISNUMBER(K6),K6>0),(L6-K6)/K6,"") | P6: 1 | Q6: HIGH | R6: =IF(ISNUMBER(G6),MAX(0,D6-Legend!$B$2*G6/7)*H6,0)
A7: APAC | B7: AP-ACC-026 | C7: Accessories | D7: 182 | E7: 44 | F7: 25 | G7: 48.75 | H7: 541.29 | I7: =IF(AND(ISNUMBER(G7),G7>0),D7/(G7/7),"") | J7: =IF(AND(ISNUMBER(E7),D7<E7),1,0) | K7: 403 | L7: 407 | M7: 42 | N7: =IF(AND(ISNUMBER(K7),K7>0),M7/K7,"") | O7: =IF(AND(ISNUMBER(K7),K7>0),(L7-K7)/K7,"") | Q7: LOW | R7: =IF(ISNUMBER(G7),MAX(0,D7-Legend!$B$2*G7/7)*H7,0)
A8: APAC | B8: AP-ACC-030 | C8: Accessories | D8: 564 | E8: 85 | F8: 32 | G8: 112.5 | H8: 757.84 | I8: =IF(AND(ISNUMBER(G8),G8>0),D8/(G8/7),"") | J8: =IF(AND(ISNUMBER(E8),D8<E8),1,0) | K8: 1039 | L8: 1032 | M8: 83 | N8: =IF(AND(ISNUMBER(K8),K8>0),M8/K8,"") | O8: =IF(AND(ISNUMBER(K8),K8>0),(L8-K8)/K8,"") | P8: 5 | Q8: MEDIUM | R8: =IF(ISNUMBER(G8),MAX(0,D8-Legend!$B$2*G8/7)*H8,0)
A9: APAC | B9: AP-ACC-034 | C9: Accessories | D9: 532 | E9: 29 | F9: 21 | G9: 58 | H9: 707.86 | I9: =IF(AND(ISNUMBER(G9),G9>0),D9/(G9/7),"") | J9: =IF(AND(ISNUMBER(E9),D9<E9),1,0) | K9: 493 | L9: 480 | M9: 131 | N9: =IF(AND(ISNUMBER(K9),K9>0),M9/K9,"") | O9: =IF(AND(ISNUMBER(K9),K9>0),(L9-K9)/K9,"") | Q9: LOW | R9: =IF(ISNUMBER(G9),MAX(0,D9-Legend!$B$2*G9/7)*H9,0)
A10: APAC | B10: AP-ACC-038 | C10: Accessories | D10: 205 | E10: 28 | F10: 21 | G10: 47 | H10: 374.67 | I10: =IF(AND(ISNUMBER(G10),G10>0),D10/(G10/7),"") | J10: =IF(AND(ISNUMBER(E10),D10<E10),1,0) | K10: 420 | L10: 399 | M10: 55 | N10: =IF(AND(ISNUMBER(K10),K10>0),M10/K10,"") | O10: =IF(AND(ISNUMBER(K10),K10>0),(L10-K10)/K10,"") | Q10: LOW | R10: =IF(ISNUMBER(G10),MAX(0,D10-Legend!$B$2*G10/7)*H10,0)
A11: APAC | B11: AP-ACC-042 | C11: Accessories | D11: 523 | E11: 80 | F11: 24 | G11: 162.75 | H11: 732.7 | I11: =IF(AND(ISNUMBER(G11),G11>0),D11/(G11/7),"") | J11: =IF(AND(ISNUMBER(E11),D11<E11),1,0) | K11: 1321 | L11: 1419 | M11: 206 | N11: =IF(AND(ISNUMBER(K11),K11>0),M11/K11,"") | O11: =IF(AND(ISNUMBER(K11),K11>0),(L11-K11)/K11,"") | P11: 5 | Q11: MEDIUM | R11: =IF(ISNUMBER(G11),MAX(0,D11-Legend!$B$2*G11/7)*H11,0)
A12: APAC | B12: AP-DEV-001 | C12: Devices | D12: 5327 | E12: 68 | F12: 24 | G12: 140.25 | H12: 295.6 | I12: =IF(AND(ISNUMBER(G12),G12>0),D12/(G12/7),"") | J12: =IF(AND(ISNUMBER(E12),D12<E12),1,0) | K12: 1070 | L12: 1189 | M12: 251 | N12: =IF(AND(ISNUMBER(K12),K12>0),M12/K12,"") | O12: =IF(AND(ISNUMBER(K12),K12>0),(L12-K12)/K12,"") | Q12: LOW | R12: =IF(ISNUMBER(G12),MAX(0,D12-Legend!$B$2*G12/7)*H12,0)
A13: APAC | B13: AP-DEV-005 | C13: Devices | D13: 315 | E13: 13 | F13: 22 | G13: 19.25 | H13: 99.66 | I13: =IF(AND(ISNUMBER(G13),G13>0),D13/(G13/7),"") | J13: =IF(AND(ISNUMBER(E13),D13<E13),1,0) | K13: 217 | L13: 161 | M13: 64 | N13: =IF(AND(ISNUMBER(K13),K13>0),M13/K13,"") | O13: =IF(AND(ISNUMBER(K13),K13>0),(L13-K13)/K13,"") | Q13: LOW | R13: =IF(ISNUMBER(G13),MAX(0,D13-Legend!$B$2*G13/7)*H13,0)
A14: APAC | B14: AP-DEV-009 | C14: Devices | D14: 368 | E14: 52 | F14: 22 | G14: 86.75 | H14: 529.38 | I14: =IF(AND(ISNUMBER(G14),G14>0),D14/(G14/7),"") | J14: =IF(AND(ISNUMBER(E14),D14<E14),1,0) | K14: 671 | L14: 635 | M14: 70 | N14: =IF(AND(ISNUMBER(K14),K14>0),M14/K14,"") | O14: =IF(AND(ISNUMBER(K14),K14>0),(L14-K14)/K14,"") | Q14: LOW | R14: =IF(ISNUMBER(G14),MAX(0,D14-Legend!$B$2*G14/7)*H14,0)
A15: APAC | B15: AP-DEV-013 | C15: Devices | D15: 363 | E15: 45 | F15: 15 | G15: 141.25 | H15: 101.31 | I15: =IF(AND(ISNUMBER(G15),G15>0),D15/(G15/7),"") | J15: =IF(AND(ISNUMBER(E15),D15<E15),1,0) | K15: 923 | L15: 1060 | M15: 151 | N15: =IF(AND(ISNUMBER(K15),K15>0),M15/K15,"") | O15: =IF(AND(ISNUMBER(K15),K15>0),(L15-K15)/K15,"") | P15: 3 | Q15: MEDIUM | R15: =IF(ISNUMBER(G15),MAX(0,D15-Legend!$B$2*G15/7)*H15,0)
A16: APAC | B16: AP-DEV-017 | C16: Devices | D16: 657 | E16: 78 | F16: 29 | G16: 134.5 | H16: 658.53 | I16: =IF(AND(ISNUMBER(G16),G16>0),D16/(G16/7),"") | J16: =IF(AND(ISNUMBER(E16),D16<E16),1,0) | K16: 980 | L16: 920 | M16: 122 | N16: =IF(AND(ISNUMBER(K16),K16>0),M16/K16,"") | O16: =IF(AND(ISNUMBER(K16),K16>0),(L16-K16)/K16,"") | Q16: LOW | R16: =IF(ISNUMBER(G16),MAX(0,D16-Legend!$B$2*G16/7)*H16,0)
A17: APAC | B17: AP-DEV-021 | C17: Devices | D17: 749 | E17: 58 | F17: 35 | G17: 112.75 | H17: 493.19 | I17: =IF(AND(ISNUMBER(G17),G17>0),D17/(G17/7),"") | J17: =IF(AND(ISNUMBER(E17),D17<E17),1,0) | K17: 851 | L17: 881 | M17: 120 | N17: =IF(AND(ISNUMBER(K17),K17>0),M17/K17,"") | O17: =IF(AND(ISNUMBER(K17),K17>0),(L17-K17)/K17,"") | Q17: LOW | R17: =IF(ISNUMBER(G17),MAX(0,D17-Legend!$B$2*G17/7)*H17,0)
A18: APAC | B18: AP-DEV-025 | C18: Devices | D18: 2380 | E18: 48 | F18: 34 | G18: 56.5 | H18: 244.96 | I18: =IF(AND(ISNUMBER(G18),G18>0),D18/(G18/7),"") | J18: =IF(AND(ISNUMBER(E18),D18<E18),1,0) | K18: 419 | L18: 497 | M18: 82 | N18: =IF(AND(ISNUMBER(K18),K18>0),M18/K18,"") | O18: =IF(AND(ISNUMBER(K18),K18>0),(L18-K18)/K18,"") | Q18: LOW | R18: =IF(ISNUMBER(G18),MAX(0,D18-Legend!$B$2*G18/7)*H18,0)
A19: APAC | B19: AP-DEV-029 | C19: Devices | D19: 751 | E19: 58 | F19: 15 | G19: 132.75 | H19: 67.34 | I19: =IF(AND(ISNUMBER(G19),G19>0),D19/(G19/7),"") | J19: =IF(AND(ISNUMBER(E19),D19<E19),1,0) | K19: 1206 | L19: 1149 | M19: 223 | N19: =IF(AND(ISNUMBER(K19),K19>0),M19/K19,"") | O19: =IF(AND(ISNUMBER(K19),K19>0),(L19-K19)/K19,"") | Q19: LOW | R19: =IF(ISNUMBER(G19),MAX(0,D19-Legend!$B$2*G19/7)*H19,0)
A20: APAC | B20: AP-DEV-033 | C20: Devices | D20: 274 | E20: 46 | F20: 35 | G20: 76.5 | H20: 546.52 | I20: =IF(AND(ISNUMBER(G20),G20>0),D20/(G20/7),"") | J20: =IF(AND(ISNUMBER(E20),D20<E20),1,0) | K20: 531 | L20: 521 | M20: 94 | N20: =IF(AND(ISNUMBER(K20),K20>0),M20/K20,"") | O20: =IF(AND(ISNUMBER(K20),K20>0),(L20-K20)/K20,"") | Q20: LOW | R20: =IF(ISNUMBER(G20),MAX(0,D20-Legend!$B$2*G20/7)*H20,0)
A21: APAC | B21: AP-DEV-037 | C21: Devices | D21: 221 | F21: 20 | G21: 90.75 | H21: 832.8 | I21: =IF(AND(ISNUMBER(G21),G21>0),D21/(G21/7),"") | J21: =IF(AND(ISNUMBER(E21),D21<E21),1,0) | K21: 594 | L21: 634 | M21: 112 | N21: =IF(AND(ISNUMBER(K21),K21>0),M21/K21,"") | O21: =IF(AND(ISNUMBER(K21),K21>0),(L21-K21)/K21,"") | P21: 4 | Q21: MEDIUM | R21: =IF(ISNUMBER(G21),MAX(0,D21-Legend!$B$2*G21/7)*H21,0)
A22: APAC | B22: AP-DEV-041 | C22: Devices | D22: 524 | E22: 111 | F22: 35 | G22: 144.75 | H22: 497.6 | I22: =IF(AND(ISNUMBER(G22),G22>0),D22/(G22/7),"") | J22: =IF(AND(ISNUMBER(E22),D22<E22),1,0) | K22: 1546 | L22: 1380 | M22: 220 | N22: =IF(AND(ISNUMBER(K22),K22>0),M22/K22,"") | O22: =IF(AND(ISNUMBER(K22),K22>0),(L22-K22)/K22,"") | P22: 3 | Q22: HIGH | R22: =IF(ISNUMBER(G22),MAX(0,D22-Legend!$B$2*G22/7)*H22,0)
A23: APAC | B23: AP-DEV-045 | C23: Devices | D23: 1149 | E23: 70 | F23: 33 | G23: 125.25 | H23: 602.22 | I23: =IF(AND(ISNUMBER(G23),G23>0),D23/(G23/7),"") | J23: =IF(AND(ISNUMBER(E23),D23<E23),1,0) | K23: 738 | L23: 838 | M23: 190 | N23: =IF(AND(ISNUMBER(K23),K23>0),M23/K23,"") | O23: =IF(AND(ISNUMBER(K23),K23>0),(L23-K23)/K23,"") | Q23: LOW | R23: =IF(ISNUMBER(G23),MAX(0,D23-Legend!$B$2*G23/7)*H23,0)
A24: APAC | B24: AP-NET-003 | C24: Network | D24: 445 | E24: 87 | F24: 21 | G24: 191 | H24: 457.25 | I24: =IF(AND(ISNUMBER(G24),G24>0),D24/(G24/7),"") | J24: =IF(AND(ISNUMBER(E24),D24<E24),1,0) | K24: 1615 | L24: 1494 | M24: 231 | N24: =IF(AND(ISNUMBER(K24),K24>0),M24/K24,"") | O24: =IF(AND(ISNUMBER(K24),K24>0),(L24-K24)/K24,"") | P24: 4 | Q24: MEDIUM | R24: =IF(ISNUMBER(G24),MAX(0,D24-Legend!$B$2*G24/7)*H24,0)
A25: APAC | B25: AP-NET-007 | C25: Network | D25: 234 | E25: 65 | F25: 28 | G25: 131 | H25: 105.76 | I25: =IF(AND(ISNUMBER(G25),G25>0),D25/(G25/7),"") | J25: =IF(AND(ISNUMBER(E25),D25<E25),1,0) | K25: 1042 | L25: 955 | M25: 163 | N25: =IF(AND(ISNUMBER(K25),K25>0),M25/K25,"") | O25: =IF(AND(ISNUMBER(K25),K25>0),(L25-K25)/K25,"") | P25: 1 | Q25: HIGH | R25: =IF(ISNUMBER(G25),MAX(0,D25-Legend!$B$2*G25/7)*H25,0)
A26: APAC | B26: AP-NET-011 | C26: Network | D26: 889 | E26: 77 | F26: 14 | G26: 188 | H26: 241.53 | I26: =IF(AND(ISNUMBER(G26),G26>0),D26/(G26/7),"") | J26: =IF(AND(ISNUMBER(E26),D26<E26),1,0) | K26: 1395 | L26: 1469 | M26: 176 | N26: =IF(AND(ISNUMBER(K26),K26>0),M26/K26,"") | O26: =IF(AND(ISNUMBER(K26),K26>0),(L26-K26)/K26,"") | Q26: LOW | R26: =IF(ISNUMBER(G26),MAX(0,D26-Legend!$B$2*G26/7)*H26,0)
A27: APAC | B27: AP-NET-015 | C27: Network | D27: 278 | E27: 82 | F27: 28 | G27: 182.5 | H27: 380.31 | I27: =IF(AND(ISNUMBER(G27),G27>0),D27/(G27/7),"") | J27: =IF(AND(ISNUMBER(E27),D27<E27),1,0) | K27: 1590 | L27: 1616 | M27: 184 | N27: =IF(AND(ISNUMBER(K27),K27>0),M27/K27,"") | O27: =IF(AND(ISNUMBER(K27),K27>0),(L27-K27)/K27,"") | P27: 3 | Q27: HIGH | R27: =IF(ISNUMBER(G27),MAX(0,D27-Legend!$B$2*G27/7)*H27,0)
A28: APAC | B28: AP-NET-019 | C28: Network | D28: 267 | E28: 119 | F28: 33 | G28: 218.5 | H28: 609.92 | I28: =IF(AND(ISNUMBER(G28),G28>0),D28/(G28/7),"") | J28: =IF(AND(ISNUMBER(E28),D28<E28),1,0) | K28: 1913 | L28: 1798 | M28: 297 | N28: =IF(AND(ISNUMBER(K28),K28>0),M28/K28,"") | O28: =IF(AND(ISNUMBER(K28),K28>0),(L28-K28)/K28,"") | P28: 1 | Q28: HIGH | R28: =IF(ISNUMBER(G28),MAX(0,D28-Legend!$B$2*G28/7)*H28,0)
A29: APAC | B29: AP-NET-027 | C29: Network | D29: 1025 | E29: 92 | F29: 32 | G29: 109.5 | H29: 73.31 | I29: =IF(AND(ISNUMBER(G29),G29>0),D29/(G29/7),"") | J29: =IF(AND(ISNUMBER(E29),D29<E29),1,0) | K29: 951 | L29: 962 | M29: 87 | N29: =IF(AND(ISNUMBER(K29),K29>0),M29/K29,"") | O29: =IF(AND(ISNUMBER(K29),K29>0),(L29-K29)/K29,"") | Q29: LOW | R29: =IF(ISNUMBER(G29),MAX(0,D29-Legend!$B$2*G29/7)*H29,0)
A30: APAC | B30: AP-NET-031 | C30: Network | D30: 2323 | E30: 274 | F30: 30 | G30: 623.5 | H30: 122.23 | I30: =IF(AND(ISNUMBER(G30),G30>0),D30/(G30/7),"") | J30: =IF(AND(ISNUMBER(E30),D30<E30),1,0) | K30: 4162 | L30: 4250 | M30: 702 | N30: =IF(AND(ISNUMBER(K30),K30>0),M30/K30,"") | O30: =IF(AND(ISNUMBER(K30),K30>0),(L30-K30)/K30,"") | P30: 3 | Q30: HIGH | R30: =IF(ISNUMBER(G30),MAX(0,D30-Legend!$B$2*G30/7)*H30,0)
A31: APAC | B31: AP-NET-035 | C31: Network | D31: 980 | E31: 96 | F31: 31 | G31: 153.5 | H31: 302.51 | I31: =IF(AND(ISNUMBER(G31),G31>0),D31/(G31/7),"") | J31: =IF(AND(ISNUMBER(E31),D31<E31),1,0) | K31: 1481 | L31: 1295 | M31: 242 | N31: =IF(AND(ISNUMBER(K31),K31>0),M31/K31,"") | O31: =IF(AND(ISNUMBER(K31),K31>0),(L31-K31)/K31,"") | Q31: LOW | R31: =IF(ISNUMBER(G31),MAX(0,D31-Legend!$B$2*G31/7)*H31,0)
A32: APAC | B32: AP-NET-039 | C32: Network | D32: 680 | E32: 33 | F32: 28 | G32: 53 | H32: 168.42 | I32: =IF(AND(ISNUMBER(G32),G32>0),D32/(G32/7),"") | J32: =IF(AND(ISNUMBER(E32),D32<E32),1,0) | K32: 452 | L32: 420 | M32: 64 | N32: =IF(AND(ISNUMBER(K32),K32>0),M32/K32,"") | O32: =IF(AND(ISNUMBER(K32),K32>0),(L32-K32)/K32,"") | Q32: LOW | R32: =IF(ISNUMBER(G32),MAX(0,D32-Legend!$B$2*G32/7)*H32,0)
A33: APAC | B33: AP-NET-043 | C33: Network | D33: 630 | E33: 36 | F33: 26 | G33: 52.25 | H33: 560.61 | I33: =IF(AND(ISNUMBER(G33),G33>0),D33/(G33/7),"") | J33: =IF(AND(ISNUMBER(E33),D33<E33),1,0) | K33: 489 | L33: 466 | M33: 53 | N33: =IF(AND(ISNUMBER(K33),K33>0),M33/K33,"") | O33: =IF(AND(ISNUMBER(K33),K33>0),(L33-K33)/K33,"") | Q33: LOW | R33: =IF(ISNUMBER(G33),MAX(0,D33-Legend!$B$2*G33/7)*H33,0)
A34: APAC | B34: AP-STO-004 | C34: Storage | D34: 1600 | E34: 92 | F34: 18 | G34: 179.25 | H34: 301.86 | I34: =IF(AND(ISNUMBER(G34),G34>0),D34/(G34/7),"") | J34: =IF(AND(ISNUMBER(E34),D34<E34),1,0) | K34: 1767 | L34: 1638 | M34: 235 | N34: =IF(AND(ISNUMBER(K34),K34>0),M34/K34,"") | O34: =IF(AND(ISNUMBER(K34),K34>0),(L34-K34)/K34,"") | Q34: LOW | R34: =IF(ISNUMBER(G34),MAX(0,D34-Legend!$B$2*G34/7)*H34,0)
A35: APAC | B35: AP-STO-008 | C35: Storage | D35: 241 | E35: 51 | F35: 33 | G35: 56.5 | H35: 135.83 | I35: =IF(AND(ISNUMBER(G35),G35>0),D35/(G35/7),"") | J35: =IF(AND(ISNUMBER(E35),D35<E35),1,0) | K35: 370 | L35: 435 | M35: 69 | N35: =IF(AND(ISNUMBER(K35),K35>0),M35/K35,"") | O35: =IF(AND(ISNUMBER(K35),K35>0),(L35-K35)/K35,"") | Q35: LOW | R35: =IF(ISNUMBER(G35),MAX(0,D35-Legend!$B$2*G35/7)*H35,0)
A36: APAC | B36: AP-STO-012 | C36: Storage | D36: 753 | F36: 15 | G36: 159.75 | H36: 679.67 | I36: =IF(AND(ISNUMBER(G36),G36>0),D36/(G36/7),"") | J36: =IF(AND(ISNUMBER(E36),D36<E36),1,0) | K36: 1243 | L36: 1197 | M36: 176 | N36: =IF(AND(ISNUMBER(K36),K36>0),M36/K36,"") | O36: =IF(AND(ISNUMBER(K36),K36>0),(L36-K36)/K36,"") | Q36: LOW | R36: =IF(ISNUMBER(G36),MAX(0,D36-Legend!$B$2*G36/7)*H36,0)
A37: APAC | B37: AP-STO-016 | C37: Storage | D37: 892 | E37: 25 | F37: 17 | G37: 37 | H37: 820.93 | I37: =IF(AND(ISNUMBER(G37),G37>0),D37/(G37/7),"") | J37: =IF(AND(ISNUMBER(E37),D37<E37),1,0) | K37: 337 | L37: 304 | M37: 79 | N37: =IF(AND(ISNUMBER(K37),K37>0),M37/K37,"") | O37: =IF(AND(ISNUMBER(K37),K37>0),(L37-K37)/K37,"") | Q37: LOW | R37: =IF(ISNUMBER(G37),MAX(0,D37-Legend!$B$2*G37/7)*H37,0)
A38: APAC | B38: AP-STO-020 | C38: Storage | D38: 351 | E38: 53 | F38: 24 | G38: 129 | H38: 613.64 | I38: =IF(AND(ISNUMBER(G38),G38>0),D38/(G38/7),"") | J38: =IF(AND(ISNUMBER(E38),D38<E38),1,0) | K38: 810 | L38: 935 | M38: 193 | N38: =IF(AND(ISNUMBER(K38),K38>0),M38/K38,"") | O38: =IF(AND(ISNUMBER(K38),K38>0),(L38-K38)/K38,"") | Q38: LOW | R38: =IF(ISNUMBER(G38),MAX(0,D38-Legend!$B$2*G38/7)*H38,0)
A39: APAC | B39: AP-STO-024 | C39: Storage | D39: 576 | E39: 53 | F39: 28 | G39: 114.25 | H39: 749.3 | I39: =IF(AND(ISNUMBER(G39),G39>0),D39/(G39/7),"") | J39: =IF(AND(ISNUMBER(E39),D39<E39),1,0) | K39: 759 | L39: 826 | M39: 101 | N39: =IF(AND(ISNUMBER(K39),K39>0),M39/K39,"") | O39: =IF(AND(ISNUMBER(K39),K39>0),(L39-K39)/K39,"") | Q39: LOW | R39: =IF(ISNUMBER(G39),MAX(0,D39-Legend!$B$2*G39/7)*H39,0)
A40: APAC | B40: AP-STO-028 | C40: Storage | D40: 499 | E40: 66 | F40: 21 | G40: 84 | H40: 75.89 | I40: =IF(AND(ISNUMBER(G40),G40>0),D40/(G40/7),"") | J40: =IF(AND(ISNUMBER(E40),D40<E40),1,0) | K40: 711 | L40: 764 | M40: 237 | N40: =IF(AND(ISNUMBER(K40),K40>0),M40/K40,"") | O40: =IF(AND(ISNUMBER(K40),K40>0),(L40-K40)/K40,"") | Q40: LOW | R40: =IF(ISNUMBER(G40),MAX(0,D40-Legend!$B$2*G40/7)*H40,0)
...

Sheet Accuracy_SKU
A1: market | B1: sku | C1: actual_units_8w | D1: forecast_units_8w | E1: abs_err_8w | F1: wape | G1: bias
A2: APAC | B2: AP-ACC-002 | C2: 547 | D2: 472 | E2: 79 | F2: =IF(C2>0,E2/C2,"") | G2: =IF(C2>0,(D2-C2)/C2,"")
A3: APAC | B3: AP-ACC-006 | C3: 316 | D3: 327 | E3: 65 | F3: =IF(C3>0,E3/C3,"") | G3: =IF(C3>0,(D3-C3)/C3,"")
A4: APAC | B4: AP-ACC-010 | C4: 365 | D4: 373 | E4: 58 | F4: =IF(C4>0,E4/C4,"") | G4: =IF(C4>0,(D4-C4)/C4,"")
A5: APAC | B5: AP-ACC-014 | C5: 1302 | D5: 1259 | E5: 301 | F5: =IF(C5>0,E5/C5,"") | G5: =IF(C5>0,(D5-C5)/C5,"")
A6: APAC | B6: AP-ACC-018 | C6: 411 | D6: 403 | E6: 60 | F6: =IF(C6>0,E6/C6,"") | G6: =IF(C6>0,(D6-C6)/C6,"")
A7: APAC | B7: AP-ACC-022 | C7: 440 | D7: 612 | E7: 172 | F7: =IF(C7>0,E7/C7,"") | G7: =IF(C7>0,(D7-C7)/C7,"")
A8: APAC | B8: AP-ACC-026 | C8: 403 | D8: 407 | E8: 42 | F8: =IF(C8>0,E8/C8,"") | G8: =IF(C8>0,(D8-C8)/C8,"")
A9: APAC | B9: AP-ACC-030 | C9: 1039 | D9: 1032 | E9: 83 | F9: =IF(C9>0,E9/C9,"") | G9: =IF(C9>0,(D9-C9)/C9,"")
A10: APAC | B10: AP-ACC-034 | C10: 493 | D10: 480 | E10: 131 | F10: =IF(C10>0,E10/C10,"") | G10: =IF(C10>0,(D10-C10)/C10,"")
A11: APAC | B11: AP-ACC-038 | C11: 420 | D11: 399 | E11: 55 | F11: =IF(C11>0,E11/C11,"") | G11: =IF(C11>0,(D11-C11)/C11,"")
A12: APAC | B12: AP-ACC-042 | C12: 1321 | D12: 1419 | E12: 206 | F12: =IF(C12>0,E12/C12,"") | G12: =IF(C12>0,(D12-C12)/C12,"")
A13: APAC | B13: AP-DEV-001 | C13: 1070 | D13: 1189 | E13: 251 | F13: =IF(C13>0,E13/C13,"") | G13: =IF(C13>0,(D13-C13)/C13,"")
... A151: South Africa | B151: ZA-STO-028 | C151: 355 | D151: 326 | E151: 47 | F151: =IF(C151>0,E151/C151,"") | G151: =IF(C151>0,(D151-C151)/C151,"")

Sheet OTIF_Supplier
A1: market | B1: supplier | C1: pos | D1: on_time | E1: in_full | F1: otif_pos | G1: on_time_pct | H1: in_full_pct | I1: otif_pct
A2: APAC | B2: SUP-AP-01 | C2: 32 | D2: 27 | E2: 28 | F2: 24 | G2: =D2/C2 | H2: =E2/C2 | I2: =F2/C2
A3: APAC | B3: SUP-AP-02 | C3: 39 | D3: 35 | E3: 36 | F3: 32 | G3: =D3/C3 | H3: =E3/C3 | I3: =F3/C3
A4: APAC | B4: SUP-AP-03 | C4: 23 | D4: 15 | E4: 21 | F4: 15 | G4: =D4/C4 | H4: =E4/C4 | I4: =F4/C4
A5: APAC | B5: SUP-AP-04 | C5: 34 | D5: 30 | E5: 31 | F5: 29 | G5: =D5/C5 | H5: =E5/C5 | I5: =F5/C5
A6: APAC | B6: SUP-AP-05 | C6: 33 | D6: 24 | E6: 31 | F6: 23 | G6: =D6/C6 | H6: =E6/C6 | I6: =F6/C6
A7: APAC | B7: SUP-AP-06 | C7: 42 | D7: 37 | E7: 39 | F7: 34 | G7: =D7/C7 | H7: =E7/C7 | I7: =F7/C7
A8: India | B8: SUP-IN-01 | C8: 33 | D8: 25 | E8: 28 | F8: 20 | G8: =D8/C8 | H8: =E8/C8 | I8: =F8/C8
A9: India | B9: SUP-IN-02 | C9: 37 | D9: 27 | E9: 34 | F9: 24 | G9: =D9/C9 | H9: =E9/C9 | I9: =F9/C9
A10: India | B10: SUP-IN-03 | C10: 39 | D10: 25 | E10: 33 | F10: 22 | G10: =D10/C10 | H10: =E10/C10 | I10: =F10/C10
A11: India | B11: SUP-IN-04 | C11: 28 | D11: 22 | E11: 25 | F11: 20 | G11: =D11/C11 | H11: =E11/C11 | I11: =F11/C11
A12: India | B12: SUP-IN-05 | C12: 41 | D12: 28 | E12: 33 | F12: 23 | G12: =D12/C12 | H12: =E12/C12 | I12: =F12/C12
A13: MENA-PAK | B13: SUP-MP-01 | C13: 36 | D13: 35 | E13: 35 | F13: 34 | G13: =D13/C13 | H13: =E13/C13 | I13: =F13/C13
... A21: South Africa | B21: SUP-ZA-04 | C21: 32 | D21: 24 | E21: 29 | F21: 22 | G21: =D21/C21 | H21: =E21/C21 | I21: =F21/C21

Sheet Actions
A1: action_id | B1: market | C1: severity | D1: exc_type | E1: ref | F1: owner_role | G1: description | H1: due_date | I1: status | J1: days_overdue | K1: escalation_level | L1: created_week | M1: last_seen | N1: source | O1: note
A2: ACT-0001 | B2: South Africa | C2: P2 | D2: STOCKOUT_RISK | E2: ZA-STO-016 | F2: Supply Planner, South Africa | G2: Projected stockout in week 6 of 8 (lead time 36 d, cover 8.0 d) | H2: 46319 | I2: Open | J2: 2 | K2: 1 | L2: 46314 | M2: 46321 | N2: exception
A3: ACT-0002 | B3: APAC | C3: P1 | D3: STOCKOUT_RISK | E3: AP-NET-043 | F3: Supply Planner, APAC | G3: Projected stockout in week 2 of 8 (lead time 26 d, cover 13.0 d) | H3: 46316 | I3: Resolved-Verify | J3: 0 | K3: 0 | L3: 46314 | M3: 46314 | N3: exception | O3: Not flagged in run 2026-10-26; owner to confirm and close
A4: ACT-0003 | B4: India | C4: P2 | D4: STOCKOUT_RISK | E4: IN-DEV-021 | F4: Supply Planner, India | G4: Projected stockout in week 7 of 8 (lead time 18 d, cover 30.0 d) | H4: 46319 | I4: Resolved-Verify | J4: 0 | K4: 0 | L4: 46314 | M4: 46314 | N4: exception | O4: Not flagged in run 2026-10-26; owner to confirm and close
A5: ACT-0004 | B5: India | C5: P2 | D5: STOCKOUT_RISK | E5: IN-ACC-022 | F5: Supply Planner, India | G5: Projected stockout in week 6 of 8 (lead time 21 d, cover 20.0 d) | H5: 46319 | I5: Resolved-Verify | J5: 0 | K5: 0 | L5: 46314 | M5: 46314 | N5: exception | O5: Not flagged in run 2026-10-26; owner to confirm and close
A6: ACT-0005 | B6: India | C6: P1 | D6: STOCKOUT_RISK | E6: IN-ACC-038 | F6: Supply Planner, India | G6: Projected stockout in week 4 of 8 (lead time 29 d, cover 26.0 d) | H6: 46316 | I6: In Progress | J6: 5 | K6: 2 | L6: 46314 | M6: 46321 | N6: exception | O6: Owner contacted supplier (simulated update)
A7: ACT-0006 | B7: South Africa | C7: P1 | D7: STOCKOUT_RISK | E7: ZA-DEV-025 | F7: Supply Planner, South Africa | G7: Projected stockout in week 4 of 8 (lead time 54 d, cover 20.0 d) | H7: 46316 | I7: Resolved-Verify | J7: 0 | K7: 0 | L7: 46314 | M7: 46314 | N7: exception | O7: Not flagged in run 2026-10-26; owner to confirm and close
A8: ACT-0007 | B8: South Africa | C8: P1 | D8: STOCKOUT_RISK | E8: ZA-DEV-009 | F8: Supply Planner, South Africa | G8: Projected stockout in week 4 of 8 (lead time 45 d, cover 22.0 d) | H8: 46316 | I8: Resolved-Verify | J8: 0 | K8: 0 | L8: 46314 | M8: 46314 | N8: exception | O8: Not flagged in run 2026-10-26; owner to confirm and close
A9: ACT-0008 | B9: South Africa | C9: P1 | D9: STOCKOUT_RISK | E9: ZA-STO-012 | F9: Supply Planner, South Africa | G9: Projected stockout in week 5 of 8 (lead time 65 d, cover 32.0 d) | H9: 46316 | I9: Resolved-Verify | J9: 0 | K9: 0 | L9: 46314 | M9: 46314 | N9: exception | O9: Not flagged in run 2026-10-26; owner to confirm and close
A10: ACT-0009 | B10: APAC | C10: P2 | D10: STOCKOUT_RISK | E10: AP-ACC-030 | F10: Supply Planner, APAC | G10: Projected stockout in week 6 of 8 (lead time 32 d, cover 35.0 d) | H10: 46319 | I10: Open | J10: 2 | K10: 1 | L10: 46314 | M10: 46321 | N10: exception
A11: ACT-0010 | B11: APAC | C11: P1 | D11: STOCKOUT_RISK | E11: AP-ACC-022 | F11: Supply Planner, APAC | G11: Projected stockout in week 2 of 8 (lead time 17 d, cover 9.0 d) | H11: 46316 | I11: Open | J11: 5 | K11: 2 | L11: 46314 | M11: 46321 | N11: exception
A12: ACT-0011 | B12: South Africa | C12: P2 | D12: STOCKOUT_RISK | E12: ZA-DEV-013 | F12: Supply Planner, South Africa | G12: Projected stockout in week 2 of 8 (lead time 31 d, cover 9.0 d) | H12: 46319 | I12: Open | J12: 2 | K12: 1 | L12: 46314 | M12: 46321 | N12: exception
A13: ACT-0012 | B13: APAC | C13: P2 | D13: STOCKOUT_RISK | E13: AP-ACC-038 | F13: Supply Planner, APAC | G13: Projected stockout in week 7 of 8 (lead time 21 d, cover 9.0 d) | H13: 46319 | I13: Resolved-Verify | J13: 0 | K13: 0 | L13: 46314 | M13: 46314 | N13: exception | O13: Not flagged in run 2026-10-26; owner to confirm and close
A14: ACT-0013 | B14: APAC | C14: P2 | D14: STOCKOUT_RISK | E14: AP-DEV-041 | F14: Supply Planner, APAC | G14: Projected stockout in week 4 of 8 (lead time 35 d, cover 25.0 d) | H14: 46319 | I14: Open | J14: 2 | K14: 1 | L14: 46314 | M14: 46321 | N14: exception
A15: ACT-0014 | B15: MENA-PAK | C15: P1 | D15: STOCKOUT_RISK | E15: MP-ACC-030 | F15: Supply Planner, MENA-PAK | G15: Projected stockout in week 4 of 8 (lead time 55 d, cover 7.0 d) | H15: 46316 | I15: Resolved-Verify | J15: 0 | K15: 0 | L15: 46314 | M15: 46314 | N15: exception | O15: Not flagged in run 2026-10-26; owner to confirm and close
A16: ACT-0015 | B16: India | C16: P1 | D16: STOCKOUT_RISK | E16: IN-NET-019 | F16: Supply Planner, India | G16: Projected stockout in week 3 of 8 (lead time 18 d, cover 16.0 d) | H16: 46316 | I16: Resolved-Verify | J16: 0 | K16: 0 | L16: 46314 | M16: 46314 | N16: exception | O16: Not flagged in run 2026-10-26; owner to confirm and close
A17: ACT-0016 | B17: MENA-PAK | C17: P2 | D17: STOCKOUT_RISK | E17: MP-STO-008 | F17: Supply Planner, MENA-PAK | G17: Projected stockout in week 8 of 8 (lead time 39 d, cover 31.0 d) | H17: 46319 | I17: Resolved-Verify | J17: 0 | K17: 0 | L17: 46314 | M17: 46314 | N17: exception | O17: Not flagged in run 2026-10-26; owner to confirm and close
A18: ACT-0017 | B18: MENA-PAK | C18: P1 | D18: STOCKOUT_RISK | E18: MP-NET-019 | F18: Supply Planner, MENA-PAK | G18: Projected stockout in week 1 of 8 (lead time 42 d, cover 5.0 d) | H18: 46316 | I18: Resolved-Verify | J18: 0 | K18: 0 | L18: 46314 | M18: 46314 | N18: exception | O18: Not flagged in run 2026-10-26; owner to confirm and close
A19: ACT-0018 | B19: APAC | C19: P2 | D19: STOCKOUT_RISK | E19: AP-STO-024 | F19: Supply Planner, APAC | G19: Projected stockout in week 6 of 8 (lead time 28 d, cover 32.0 d) | H19: 46319 | I19: Resolved-Verify | J19: 0 | K19: 0 | L19: 46314 | M19: 46314 | N19: exception | O19: Not flagged in run 2026-10-26; owner to confirm and close
A20: ACT-0019 | B20: India | C20: P2 | D20: STOCKOUT_RISK | E20: IN-STO-040 | F20: Supply Planner, India | G20: Projected stockout in week 7 of 8 (lead time 28 d, cover 43.0 d) | H20: 46319 | I20: Resolved-Verify | J20: 0 | K20: 0 | L20: 46314 | M20: 46314 | N20: exception | O20: Not flagged in run 2026-10-26; owner to confirm and close
A21: ACT-0020 | B21: South Africa | C21: P1 | D21: STOCKOUT_RISK | E21: ZA-DEV-005 | F21: Supply Planner, South Africa | G21: Projected stockout in week 8 of 8 (lead time 32 d, cover 32.0 d) | H21: 46316 | I21: Open | J21: 5 | K21: 2 | L21: 46314 | M21: 46321 | N21: exception
A22: ACT-0021 | B22: South Africa | C22: P2 | D22: STOCKOUT_RISK | E22: ZA-NET-011 | F22: Supply Planner, South Africa | G22: Projected stockout in week 8 of 8 (lead time 35 d, cover 17.0 d) | H22: 46319 | I22: Resolved-Verify | J22: 0 | K22: 0 | L22: 46314 | M22: 46314 | N22: exception | O22: Not flagged in run 2026-10-26; owner to confirm and close
A23: ACT-0022 | B23: South Africa | C23: P1 | D23: STOCKOUT_RISK | E23: ZA-STO-020 | F23: Supply Planner, South Africa | G23: Projected stockout in week 5 of 8 (lead time 33 d, cover 18.0 d) | H23: 46316 | I23: Resolved-Verify | J23: 0 | K23: 0 | L23: 46314 | M23: 46314 | N23: exception | O23: Not flagged in run 2026-10-26; owner to confirm and close
A24: ACT-0023 | B24: APAC | C24: P1 | D24: STOCKOUT_RISK | E24: AP-NET-019 | F24: Supply Planner, APAC | G24: Projected stockout in week 2 of 8 (lead time 33 d, cover 9.0 d) | H24: 46316 | I24: Open | J24: 5 | K24: 2 | L24: 46314 | M24: 46321 | N24: exception
A25: ACT-0024 | B25: MENA-PAK | C25: P1 | D25: STOCKOUT_RISK | E25: MP-DEV-001 | F25: Supply Planner, MENA-PAK | G25: Projected stockout in week 3 of 8 (lead time 47 d, cover 7.0 d) | H25: 46316 | I25: Resolved-Verify | J25: 0 | K25: 0 | L25: 46314 | M25: 46314 | N25: exception | O25: Not flagged in run 2026-10-26; owner to confirm and close
A26: ACT-0025 | B26: MENA-PAK | C26: P1 | D26: STOCKOUT_RISK | E26: MP-ACC-010 | F26: Supply Planner, MENA-PAK | G26: Projected stockout in week 1 of 8 (lead time 29 d, cover 4.0 d) | H26: 46316 | I26: Resolved-Verify | J26: 0 | K26: 0 | L26: 46314 | M26: 46314 | N26: exception | O26: Not flagged in run 2026-10-26; owner to confirm and close
A27: ACT-0026 | B27: South Africa | C27: P1 | D27: STOCKOUT_RISK | E27: ZA-NET-007 | F27: Supply Planner, South Africa | G27: Projected stockout in week 4 of 8 (lead time 57 d, cover 26.0 d) | H27: 46316 | I27: Resolved-Verify | J27: 0 | K27: 0 | L27: 46314 | M27: 46314 | N27: exception | O27: Not flagged in run 2026-10-26; owner to confirm and close
A28: ACT-0027 | B28: South Africa | C28: P2 | D28: STOCKOUT_RISK | E28: ZA-NET-023 | F28: Supply Planner, South Africa | G28: Projected stockout in week 8 of 8 (lead time 49 d, cover 11.0 d) | H28: 46319 | I28: Resolved-Verify | J28: 0 | K28: 0 | L28: 46314 | M28: 46314 | N28: exception | O28: Not flagged in run 2026-10-26; owner to confirm and close
A29: ACT-0028 | B29: APAC | C29: P1 | D29: STOCKOUT_RISK | E29: AP-DEV-045 | F29: Supply Planner, APAC | G29: Projected stockout in week 5 of 8 (lead time 33 d, cover 8.0 d) | H29: 46316 | I29: Resolved-Verify | J29: 0 | K29: 0 | L29: 46314 | M29: 46314 | N29: exception | O29: Not flagged in run 2026-10-26; owner to confirm and close
A30: ACT-0029 | B30: India | C30: P2 | D30: STOCKOUT_RISK | E30: IN-DEV-037 | F30: Supply Planner, India | G30: Projected stockout in week 5 of 8 (lead time 15 d, cover 19.0 d) | H30: 46319 | I30: Resolved-Verify | J30: 0 | K30: 0 | L30: 46314 | M30: 46314 | N30: exception | O30: Not flagged in run 2026-10-26; owner to confirm and close
A31: ACT-0030 | B31: MENA-PAK | C31: P2 | D31: BELOW_SAFETY | E31: MP-ACC-022 | F31: Supply Planner, MENA-PAK | G31: On hand 64 is below safety stock 77 | H31: 46319 | I31: Resolved-Verify | J31: 0 | K31: 0 | L31: 46314 | M31: 46314 | N31: exception | O31: Not flagged in run 2026-10-26; owner to confirm and close
A32: ACT-0031 | B32: South Africa | C32: P3 | D32: EXCESS_STOCK | E32: ZA-STO-024 | F32: Inventory Planner, South Africa | G32: Cover 199.0 d exceeds 120 d; excess value 96384.0 | H32: 46324 | I32: Open | J32: 0 | K32: 0 | L32: 46314 | M32: 46321 | N32: exception
A33: ACT-0032 | B33: India | C33: P3 | D33: EXCESS_STOCK | E33: IN-DEV-025 | F33: Inventory Planner, India | G33: Cover 159.0 d exceeds 120 d; excess value 230040.0 | H33: 46324 | I33: Resolved-Verify | J33: 0 | K33: 0 | L33: 46314 | M33: 46314 | N33: exception | O33: Not flagged in run 2026-10-26; owner to confirm and close
A34: ACT-0033 | B34: India | C34: P3 | D34: EXCESS_STOCK | E34: IN-ACC-026 | F34: Inventory Planner, India | G34: Cover 225.0 d exceeds 120 d; excess value 501427.0 | H34: 46324 | I34: Resolved-Verify | J34: 0 | K34: 0 | L34: 46314 | M34: 46314 | N34: exception | O34: Not flagged in run 2026-10-26; owner to confirm and close
A35: ACT-0034 | B35: MENA-PAK | C35: P3 | D35: EXCESS_STOCK | E35: MP-ACC-006 | F35: Inventory Planner, MENA-PAK | G35: Cover 221.0 d exceeds 120 d; excess value 132364.0 | H35: 46324 | I35: Resolved-Verify | J35: 0 | K35: 0 | L35: 46314 | M35: 46314 | N35: exception | O35: Not flagged in run 2026-10-26; owner to confirm and close
A36: ACT-0035 | B36: APAC | C36: P3 | D36: EXCESS_STOCK | E36: AP-NET-011 | F36: Inventory Planner, APAC | G36: Cover 263.0 d exceeds 120 d; excess value 930167.0 | H36: 46324 | I36: Resolved-Verify | J36: 0 | K36: 0 | L36: 46314 | M36: 46314 | N36: exception | O36: Not flagged in run 2026-10-26; owner to confirm and close
A37: ACT-0036 | B37: APAC | C37: P3 | D37: EXCESS_STOCK | E37: AP-NET-003 | F37: Inventory Planner, APAC | G37: Cover 216.0 d exceeds 120 d; excess value 1197864.0 | H37: 46324 | I37: Resolved-Verify | J37: 0 | K37: 0 | L37: 46314 | M37: 46314 | N37: exception | O37: Not flagged in run 2026-10-26; owner to confirm and close
A38: ACT-0037 | B38: APAC | C38: P3 | D38: EXCESS_STOCK | E38: AP-DEV-021 | F38: Inventory Planner, APAC | G38: Cover 243.0 d exceeds 120 d; excess value 978066.0 | H38: 46324 | I38: Resolved-Verify | J38: 0 | K38: 0 | L38: 46314 | M38: 46314 | N38: exception | O38: Not flagged in run 2026-10-26; owner to confirm and close
A39: ACT-0038 | B39: APAC | C39: P3 | D39: EXCESS_STOCK | E39: AP-NET-027 | F39: Inventory Planner, APAC | G39: Cover 130.0 d exceeds 120 d; excess value 11866.0 | H39: 46324 | I39: Resolved-Verify | J39: 0 | K39: 0 | L39: 46314 | M39: 46314 | N39: exception | O39: Not flagged in run 2026-10-26; owner to confirm and close
A40: ACT-0039 | B40: APAC | C40: P3 | D40: EXCESS_STOCK | E40: AP-NET-035 | F40: Inventory Planner, APAC | G40: Cover 230.0 d exceeds 120 d; excess value 730735.0 | H40: 46324 | I40: Resolved-Verify | J40: 0 | K40: 0 | L40: 46314 | M40: 46314 | N40: exception | O40: Not flagged in run 2026-10-26; owner to confirm and close
...

Sheet Exceptions
A1: market | B1: severity | C1: exc_type | D1: ref | E1: sku | F1: supplier | G1: detail | H1: owner_role
A2: APAC | B2: P1 | C2: DATA_QUALITY | D2: PO_ORPHAN | G2: PO references a SKU that is not in the inventory master: 2 row(s) | H2: Data Steward, APAC
A3: APAC | B3: P1 | C3: DATA_QUALITY | D3: INV_STALE | G3: Inventory snapshot older than 3 days at run date: 47 row(s) | H3: Data Steward, APAC
A4: APAC | B4: P1 | C4: DATA_QUALITY | D4: INV_NEG_ONHAND | G4: Negative on-hand quantity in inventory extract: 2 row(s) | H4: Data Steward, APAC
A5: APAC | B5: P1 | C5: LATE_PO | D5: PO000088 | E5: AP-NET-015 | F5: SUP-AP-03 | G5: PO PO000088 is 7 days past promised date, open qty 696 | H5: Procurement Lead, APAC
A6: APAC | B6: P1 | C6: STOCKOUT_RISK | D6: AP-ACC-022 | E6: AP-ACC-022 | G6: Projected stockout in week 2 of 8 (lead time 17 d, cover 9.0 d) | H6: Supply Planner, APAC
A7: APAC | B7: P1 | C7: STOCKOUT_RISK | D7: AP-NET-015 | E7: AP-NET-015 | G7: Projected stockout in week 4 of 8 (lead time 28 d, cover 11.0 d) | H7: Supply Planner, APAC
A8: APAC | B8: P1 | C8: STOCKOUT_RISK | D8: AP-NET-019 | E8: AP-NET-019 | G8: Projected stockout in week 2 of 8 (lead time 33 d, cover 9.0 d) | H8: Supply Planner, APAC
A9: APAC | B9: P1 | C9: STOCKOUT_RISK | D9: AP-DEV-041 | E9: AP-DEV-041 | G9: Projected stockout in week 4 of 8 (lead time 35 d, cover 25.0 d) | H9: Supply Planner, APAC
A10: APAC | B10: P1 | C10: STOCKOUT_RISK | D10: AP-NET-007 | E10: AP-NET-007 | G10: Projected stockout in week 2 of 8 (lead time 28 d, cover 13.0 d) | H10: Supply Planner, APAC
A11: APAC | B11: P1 | C11: STOCKOUT_RISK | D11: AP-NET-031 | E11: AP-NET-031 | G11: Projected stockout in week 4 of 8 (lead time 30 d, cover 26.0 d) | H11: Supply Planner, APAC
A12: India | B12: P1 | C12: DATA_QUALITY | D12: PO_ORPHAN | G12: PO references a SKU that is not in the inventory master: 2 row(s) | H12: Data Steward, India
A13: India | B13: P1 | C13: DATA_QUALITY | D13: INV_NEG_ONHAND | G13: Negative on-hand quantity in inventory extract: 2 row(s) | H13: Data Steward, India
A14: India | B14: P1 | C14: LATE_PO | D14: PO000101 | E14: IN-STO-016 | F14: SUP-IN-03 | G14: PO PO000101 is 1 days past promised date, open qty 200 | H14: Procurement Lead, India
A15: India | B15: P1 | C15: LATE_PO | D15: PO000106 | E15: IN-DEV-017 | F15: SUP-IN-04 | G15: PO PO000106 is 9 days past promised date, open qty 150 | H15: Procurement Lead, India
A16: India | B16: P1 | C16: LATE_PO | D16: PO000023 | E16: IN-STO-004 | F16: SUP-IN-03 | G16: PO PO000023 is 3 days past promised date, open qty 189 | H16: Procurement Lead, India
A17: India | B17: P1 | C17: STOCKOUT_RISK | D17: IN-STO-016 | E17: IN-STO-016 | G17: Projected stockout in week 2 of 8 (lead time 14 d, cover 11.0 d) | H17: Supply Planner, India
A18: India | B18: P1 | C18: STOCKOUT_RISK | D18: IN-DEV-017 | E18: IN-DEV-017 | G18: Projected stockout in week 1 of 8 (lead time 12 d, cover 6.0 d) | H18: Supply Planner, India
A19: India | B19: P1 | C19: STOCKOUT_RISK | D19: IN-STO-036 | E19: IN-STO-036 | G19: Projected stockout in week 2 of 8 (lead time 14 d, cover 12.0 d) | H19: Supply Planner, India
A20: India | B20: P1 | C20: STOCKOUT_RISK | D20: IN-STO-004 | E20: IN-STO-004 | G20: Projected stockout in week 2 of 8 (lead time 16 d, cover 10.0 d) | H20: Supply Planner, India
A21: India | B21: P1 | C21: STOCKOUT_RISK | D21: IN-ACC-038 | E21: IN-ACC-038 | G21: Projected stockout in week 4 of 8 (lead time 29 d, cover 26.0 d) | H21: Supply Planner, India
A22: India | B22: P1 | C22: STOCKOUT_RISK | D22: IN-NET-031 | E22: IN-NET-031 | G22: Projected stockout in week 2 of 8 (lead time 29 d, cover 11.0 d) | H22: Supply Planner, India
A23: MENA-PAK | B23: P1 | C23: DATA_QUALITY | D23: INV_NEG_ONHAND | G23: Negative on-hand quantity in inventory extract: 2 row(s) | H23: Data Steward, MENA-PAK
A24: MENA-PAK | B24: P1 | C24: DATA_QUALITY | D24: PO_ORPHAN | G24: PO references a SKU that is not in the inventory master: 2 row(s) | H24: Data Steward, MENA-PAK
A25: MENA-PAK | B25: P1 | C25: STOCKOUT_RISK | D25: MP-STO-028 | E25: MP-STO-028 | G25: Projected stockout in week 7 of 8 (lead time 50 d, cover 30.0 d) | H25: Supply Planner, MENA-PAK
A26: MENA-PAK | B26: P1 | C26: STOCKOUT_RISK | D26: MP-NET-015 | E26: MP-NET-015 | G26: Projected stockout in week 7 of 8 (lead time 53 d, cover 20.0 d) | H26: Supply Planner, MENA-PAK
A27: South Africa | B27: P1 | C27: DATA_QUALITY | D27: INV_NEG_ONHAND | G27: Negative on-hand quantity in inventory extract: 2 row(s) | H27: Data Steward, South Africa
A28: South Africa | B28: P1 | C28: DATA_QUALITY | D28: PO_ORPHAN | G28: PO references a SKU that is not in the inventory master: 2 row(s) | H28: Data Steward, South Africa
A29: South Africa | B29: P1 | C29: STOCKOUT_RISK | D29: ZA-DEV-013 | E29: ZA-DEV-013 | G29: Projected stockout in week 2 of 8 (lead time 31 d, cover 9.0 d) | H29: Supply Planner, South Africa
A30: South Africa | B30: P1 | C30: STOCKOUT_RISK | D30: ZA-STO-016 | E30: ZA-STO-016 | G30: Projected stockout in week 6 of 8 (lead time 36 d, cover 8.0 d) | H30: Supply Planner, South Africa
A31: APAC | B31: P2 | C31: DATA_QUALITY | D31: PO_DATE_ORDER | G31: PO promised date earlier than order date: 2 row(s) | H31: Data Steward, APAC
A32: APAC | B32: P2 | C32: DATA_QUALITY | D32: INV_NULL_SS | G32: Missing safety stock value: 2 row(s) | H32: Data Steward, APAC
A33: APAC | B33: P2 | C33: DATA_QUALITY | D33: INV_DUP | G33: Duplicate (market, sku) rows in inventory extract: 2 row(s) | H33: Data Steward, APAC
A34: APAC | B34: P2 | C34: DATA_QUALITY | D34: FC_NULL | G34: Forecast row with missing quantity: 3 row(s) | H34: Data Steward, APAC
A35: APAC | B35: P2 | C35: FORECAST_BIAS | D35: AP-DEV-005 | E35: AP-DEV-005 | G35: Bias -26.0% over last 8 weeks (WAPE 29.0%) | H35: Demand Planner, APAC
A36: APAC | B36: P2 | C36: FORECAST_BIAS | D36: AP-ACC-022 | E36: AP-ACC-022 | G36: Bias 39.0% over last 8 weeks (WAPE 39.0%) | H36: Demand Planner, APAC
A37: APAC | B37: P2 | C37: FORECAST_BIAS | D37: AP-NET-023 | E37: AP-NET-023 | G37: Bias -32.0% over last 8 weeks (WAPE 32.0%) | H37: Demand Planner, APAC
A38: APAC | B38: P2 | C38: LATE_PO | D38: PO000070 | E38: AP-STO-012 | F38: SUP-AP-06 | G38: PO PO000070 is 5 days past promised date, open qty 732 | H38: Procurement Lead, APAC
A39: APAC | B39: P2 | C39: LATE_PO | D39: PO000160 | E39: AP-DEV-029 | F39: SUP-AP-02 | G39: PO PO000160 is 5 days past promised date, open qty 691 | H39: Procurement Lead, APAC
A40: APAC | B40: P2 | C40: LATE_PO | D40: PO000036 | E40: AP-ACC-006 | F40: SUP-AP-01 | G40: PO PO000036 is 10 days past promised date, open qty 136 | H40: Procurement Lead, APAC
...

Sheet DQ_Results
A1: market | B1: check_id | C1: severity | D1: description | E1: n_fail | F1: status
A2: APAC | B2: INV_DUP | C2: MEDIUM | D2: Duplicate (market, sku) rows in inventory extract | E2: 2 | F2: FAIL
A3: India | B3: INV_DUP | C3: MEDIUM | D3: Duplicate (market, sku) rows in inventory extract | E3: 2 | F3: FAIL
A4: MENA-PAK | B4: INV_DUP | C4: MEDIUM | D4: Duplicate (market, sku) rows in inventory extract | E4: 2 | F4: FAIL
A5: South Africa | B5: INV_DUP | C5: MEDIUM | D5: Duplicate (market, sku) rows in inventory extract | E5: 2 | F5: FAIL
A6: APAC | B6: INV_NEG_ONHAND | C6: HIGH | D6: Negative on-hand quantity in inventory extract | E6: 2 | F6: FAIL
A7: India | B7: INV_NEG_ONHAND | C7: HIGH | D7: Negative on-hand quantity in inventory extract | E7: 2 | F7: FAIL
A8: MENA-PAK | B8: INV_NEG_ONHAND | C8: HIGH | D8: Negative on-hand quantity in inventory extract | E8: 2 | F8: FAIL
A9: South Africa | B9: INV_NEG_ONHAND | C9: HIGH | D9: Negative on-hand quantity in inventory extract | E9: 2 | F9: FAIL
A10: APAC | B10: INV_NULL_SS | C10: MEDIUM | D10: Missing safety stock value | E10: 2 | F10: FAIL
A11: India | B11: INV_NULL_SS | C11: MEDIUM | D11: Missing safety stock value | E11: 2 | F11: FAIL
A12: MENA-PAK | B12: INV_NULL_SS | C12: MEDIUM | D12: Missing safety stock value | E12: 2 | F12: FAIL
A13: South Africa | B13: INV_NULL_SS | C13: MEDIUM | D13: Missing safety stock value | E13: 2 | F13: FAIL
... A41: South Africa | B41: PO_QTY | C41: LOW | D41: PO with non-positive ordered quantity | E41: 0 | F41: PASS
